# Вашей программе будет доступна функция foo, которая может бросать исключения.

# Вам необходимо написать код, который запускает эту функцию, затем ловит исключения ArithmeticError,
# AssertionError, ZeroDivisionError и выводит имя пойманного исключения.

# Пример решения, которое вы должны отправить на проверку.

# try:
#     foo()
# except Exception:
#     print("Exception")
# except BaseException:
#     print("BaseException")
# Подсказка: https://docs.python.org/3/library/exceptions.html#exception-hierarchy

def foo():
    a = 0
    assert a != 0, "a can't be equal 0"
    b = 1 / a


try:
    foo()
except ZeroDivisionError:
    print("ZeroDivisionError")
except ArithmeticError:
    print("ArithmeticError")
except AssertionError:
    print("AssertionError")


'''ASSERT
Используется для проверки истинности указанного утверждения.
Инструкция assert позволяет производить проверки истинности утверждений, что может быть использовано в отладочных целях.
Если проверка не прошла, возбуждается исключение AssertionError.

Рекомендуется использовать инструкцию только для проверки внутреннего состояния программы — ситуаций, 
которые не должны происходить вовсе, которые нельзя обработать или это не имеет смысла (обычно это является указанием 
на то, что код программы содержит ошибку). Инструкция также может использоваться для документирования ожиданий 
(например, входных параметров или результата). В остальных случаях следует определять свои типы исключений.'''
